2020-09-21 22:09:04 INFO Core.py:9 - Jarvis instance started
2020-09-21 22:09:09 ERROR OSWindows.py:86 - 'NoneType' object has no attribute 'group'
2020-09-21 22:09:39 ERROR OSWindows.py:42 - Could not understand audio
2020-09-21 22:14:49 INFO Core.py:9 - Jarvis instance started
2020-09-21 22:14:56 ERROR OSWindows.py:42 - Could not understand audio
2020-09-21 22:15:23 INFO Core.py:9 - Jarvis instance started
2020-09-21 22:15:41 ERROR OSWindows.py:76 - Could not speak
Traceback (most recent call last):
  File "OSWindows.py", line 71, in speak
    tts.save(self.dir + str(self.count) + ".mp3")
  File "D:\Program Files\Python364\lib\site-packages\gtts\tts.py", line 111, in save
    self.write_to_fp(f)
  File "D:\Program Files\Python364\lib\site-packages\gtts\tts.py", line 124, in write_to_fp
    'tk' : self.token.calculate_token(part)}
  File "D:\Program Files\Python364\lib\site-packages\gtts_token\gtts_token.py", line 28, in calculate_token
    seed = self._get_token_key()
  File "D:\Program Files\Python364\lib\site-packages\gtts_token\gtts_token.py", line 61, in _get_token_key
    tkk_expr = re.search(".*?(TKK=.*?;)W.*?", line).group(1)
AttributeError: 'NoneType' object has no attribute 'group'
2020-09-21 22:15:41 ERROR OSWindows.py:87 - 'NoneType' object has no attribute 'group'
2020-09-21 22:15:43 ERROR OSWindows.py:42 - Could not understand audio
2020-09-21 22:17:22 INFO Core.py:9 - Jarvis instance started
2020-09-21 22:17:29 ERROR OSWindows.py:76 - Could not speak
Traceback (most recent call last):
  File "OSWindows.py", line 71, in speak
    tts.save(self.dir + str(self.count) + ".mp3")
  File "D:\Program Files\Python364\lib\site-packages\gtts\tts.py", line 111, in save
    self.write_to_fp(f)
  File "D:\Program Files\Python364\lib\site-packages\gtts\tts.py", line 124, in write_to_fp
    'tk' : self.token.calculate_token(part)}
  File "D:\Program Files\Python364\lib\site-packages\gtts_token\gtts_token.py", line 28, in calculate_token
    seed = self._get_token_key()
  File "D:\Program Files\Python364\lib\site-packages\gtts_token\gtts_token.py", line 61, in _get_token_key
    tkk_expr = re.search(".*?(TKK=.*?;)W.*?", line).group(1)
AttributeError: 'NoneType' object has no attribute 'group'
2020-09-21 22:17:54 ERROR OSWindows.py:42 - Could not understand audio
2020-09-25 19:13:52 INFO Core.py:9 - Jarvis started
2020-09-25 19:14:47 ERROR OSWindows.py:49 - Could not understand audio, temporarily reverting to standard input
Traceback (most recent call last):
  File "OSWindows.py", line 47, in listen
    cmd = self.listener.recognize_google(audio, language="en-GB")
  File "D:\Program Files\Python364\lib\site-packages\speech_recognition\__init__.py", line 858, in recognize_google
    if not isinstance(actual_result, dict) or len(actual_result.get("alternative", [])) == 0: raise UnknownValueError()
speech_recognition.UnknownValueError
2020-09-25 19:16:18 INFO Core.py:9 - Jarvis started
2020-09-25 19:16:37 WARNING OSWindows.py:50 - Could not understand audio, try again
Traceback (most recent call last):
  File "OSWindows.py", line 47, in listen
    cmd = self.listener.recognize_google(audio, language="en-GB")
  File "D:\Program Files\Python364\lib\site-packages\speech_recognition\__init__.py", line 858, in recognize_google
    if not isinstance(actual_result, dict) or len(actual_result.get("alternative", [])) == 0: raise UnknownValueError()
speech_recognition.UnknownValueError
2020-09-25 19:16:56 INFO Core.py:9 - Jarvis started
2020-09-25 19:17:15 WARNING OSWindows.py:50 - Could not understand audio, try again
Traceback (most recent call last):
  File "OSWindows.py", line 47, in listen
    cmd = self.listener.recognize_google(audio, language="en-GB")
  File "D:\Program Files\Python364\lib\site-packages\speech_recognition\__init__.py", line 858, in recognize_google
    if not isinstance(actual_result, dict) or len(actual_result.get("alternative", [])) == 0: raise UnknownValueError()
speech_recognition.UnknownValueError
2020-09-25 19:17:15 ERROR OSWindows.py:70 - Unknown error when listening, permanently reverting to standard input
Traceback (most recent call last):
  File "OSWindows.py", line 47, in listen
    cmd = self.listener.recognize_google(audio, language="en-GB")
  File "D:\Program Files\Python364\lib\site-packages\speech_recognition\__init__.py", line 858, in recognize_google
    if not isinstance(actual_result, dict) or len(actual_result.get("alternative", [])) == 0: raise UnknownValueError()
speech_recognition.UnknownValueError

During handling of the above exception, another exception occurred:

Traceback (most recent call last):
  File "OSWindows.py", line 66, in input_
    cmd = self.listen()
  File "OSWindows.py", line 51, in listen
    return listen()
NameError: name 'listen' is not defined
2020-09-25 19:18:09 INFO Core.py:9 - Jarvis started
2020-09-25 19:18:15 ERROR OSWindows.py:133 - Unknown error when speaking, permanently reverting to standard output
Traceback (most recent call last):
  File "OSWindows.py", line 131, in output
    errored = self.speak(response)
  File "OSWindows.py", line 115, in speak
    audio.save(file_location)
  File "D:\Program Files\Python364\lib\site-packages\gtts\tts.py", line 294, in save
    with open(str(savefile), 'wb') as f:
PermissionError: [Errno 13] Permission denied: 'C:/Users/defaultuser0/Music/0.mp3'
2020-09-25 19:18:21 WARNING OSWindows.py:50 - Could not understand audio, try again
Traceback (most recent call last):
  File "OSWindows.py", line 47, in listen
    cmd = self.listener.recognize_google(audio, language="en-GB")
  File "D:\Program Files\Python364\lib\site-packages\speech_recognition\__init__.py", line 858, in recognize_google
    if not isinstance(actual_result, dict) or len(actual_result.get("alternative", [])) == 0: raise UnknownValueError()
speech_recognition.UnknownValueError
2020-09-25 19:18:39 WARNING OSWindows.py:50 - Could not understand audio, try again
Traceback (most recent call last):
  File "OSWindows.py", line 47, in listen
    cmd = self.listener.recognize_google(audio, language="en-GB")
  File "D:\Program Files\Python364\lib\site-packages\speech_recognition\__init__.py", line 858, in recognize_google
    if not isinstance(actual_result, dict) or len(actual_result.get("alternative", [])) == 0: raise UnknownValueError()
speech_recognition.UnknownValueError
2020-09-25 19:20:06 INFO Core.py:9 - Jarvis started
2020-09-25 19:20:29 ERROR OSWindows.py:71 - Unknown error when listening, permanently reverting to standard input
Traceback (most recent call last):
  File "OSWindows.py", line 67, in input_
    cmd = self.listen()
  File "OSWindows.py", line 44, in listen
    IO.stout("Recognising...")
AttributeError: module 'IO' has no attribute 'stout'
2020-09-25 19:20:43 INFO Core.py:9 - Jarvis started
2020-09-25 19:20:49 ERROR OSWindows.py:134 - Unknown error when speaking, permanently reverting to standard output
Traceback (most recent call last):
  File "OSWindows.py", line 132, in output
    errored = self.speak(response)
  File "OSWindows.py", line 116, in speak
    audio.save(file_location)
  File "D:\Program Files\Python364\lib\site-packages\gtts\tts.py", line 294, in save
    with open(str(savefile), 'wb') as f:
PermissionError: [Errno 13] Permission denied: 'C:/Users/defaultuser0/Music/0.mp3'
2020-09-25 19:22:14 INFO Core.py:9 - Jarvis started
2020-09-25 19:23:05 ERROR OSWindows.py:134 - Unknown error when speaking, permanently reverting to standard output
Traceback (most recent call last):
  File "OSWindows.py", line 132, in output
    errored = self.speak(response)
  File "OSWindows.py", line 116, in speak
    audio.save(file_location)
  File "D:\Program Files\Python364\lib\site-packages\gtts\tts.py", line 294, in save
    with open(str(savefile), 'wb') as f:
PermissionError: [Errno 13] Permission denied: 'C:/Users/defaultuser0/Music/0.mp3'
2020-09-25 19:23:18 WARNING OSWindows.py:51 - Could not understand audio, try again
Traceback (most recent call last):
  File "OSWindows.py", line 48, in listen
    cmd = self.listener.recognize_google(audio, language="en-GB")
  File "D:\Program Files\Python364\lib\site-packages\speech_recognition\__init__.py", line 858, in recognize_google
    if not isinstance(actual_result, dict) or len(actual_result.get("alternative", [])) == 0: raise UnknownValueError()
speech_recognition.UnknownValueError
2020-09-25 19:23:45 WARNING OSWindows.py:51 - Could not understand audio, try again
Traceback (most recent call last):
  File "OSWindows.py", line 48, in listen
    cmd = self.listener.recognize_google(audio, language="en-GB")
  File "D:\Program Files\Python364\lib\site-packages\speech_recognition\__init__.py", line 858, in recognize_google
    if not isinstance(actual_result, dict) or len(actual_result.get("alternative", [])) == 0: raise UnknownValueError()
speech_recognition.UnknownValueError

During handling of the above exception, another exception occurred:

Traceback (most recent call last):
  File "OSWindows.py", line 48, in listen
    cmd = self.listener.recognize_google(audio, language="en-GB")
  File "D:\Program Files\Python364\lib\site-packages\speech_recognition\__init__.py", line 858, in recognize_google
    if not isinstance(actual_result, dict) or len(actual_result.get("alternative", [])) == 0: raise UnknownValueError()
speech_recognition.UnknownValueError
2020-09-25 19:23:53 WARNING OSWindows.py:51 - Could not understand audio, try again
Traceback (most recent call last):
  File "OSWindows.py", line 48, in listen
    cmd = self.listener.recognize_google(audio, language="en-GB")
  File "D:\Program Files\Python364\lib\site-packages\speech_recognition\__init__.py", line 858, in recognize_google
    if not isinstance(actual_result, dict) or len(actual_result.get("alternative", [])) == 0: raise UnknownValueError()
speech_recognition.UnknownValueError

During handling of the above exception, another exception occurred:

Traceback (most recent call last):
  File "OSWindows.py", line 48, in listen
    cmd = self.listener.recognize_google(audio, language="en-GB")
  File "D:\Program Files\Python364\lib\site-packages\speech_recognition\__init__.py", line 858, in recognize_google
    if not isinstance(actual_result, dict) or len(actual_result.get("alternative", [])) == 0: raise UnknownValueError()
speech_recognition.UnknownValueError

During handling of the above exception, another exception occurred:

Traceback (most recent call last):
  File "OSWindows.py", line 48, in listen
    cmd = self.listener.recognize_google(audio, language="en-GB")
  File "D:\Program Files\Python364\lib\site-packages\speech_recognition\__init__.py", line 858, in recognize_google
    if not isinstance(actual_result, dict) or len(actual_result.get("alternative", [])) == 0: raise UnknownValueError()
speech_recognition.UnknownValueError
2020-09-25 19:28:43 INFO Core.py:9 - Jarvis started
2020-09-25 19:29:29 INFO Core.py:9 - Jarvis started
2020-09-25 19:29:37 ERROR OSWindows.py:118 - Don't have permission to save file, permanently reverting to standard output
Traceback (most recent call last):
  File "OSWindows.py", line 116, in speak
    audio.save(file_location)
  File "D:\Program Files\Python364\lib\site-packages\gtts\tts.py", line 294, in save
    with open(str(savefile), 'wb') as f:
PermissionError: [Errno 13] Permission denied: 'C:/Users/defaultuser0/Music/0.mp3'
2020-09-25 19:29:42 WARNING OSWindows.py:51 - Could not understand audio, try again
Traceback (most recent call last):
  File "OSWindows.py", line 48, in listen
    cmd = self.listener.recognize_google(audio, language="en-GB")
  File "D:\Program Files\Python364\lib\site-packages\speech_recognition\__init__.py", line 858, in recognize_google
    if not isinstance(actual_result, dict) or len(actual_result.get("alternative", [])) == 0: raise UnknownValueError()
speech_recognition.UnknownValueError
2020-09-25 19:29:48 ERROR OSWindows.py:118 - Don't have permission to save file, permanently reverting to standard output
Traceback (most recent call last):
  File "OSWindows.py", line 116, in speak
    audio.save(file_location)
  File "D:\Program Files\Python364\lib\site-packages\gtts\tts.py", line 294, in save
    with open(str(savefile), 'wb') as f:
PermissionError: [Errno 13] Permission denied: 'C:/Users/defaultuser0/Music/0.mp3'
2020-09-30 22:28:44 INFO Core.py:9 - Jarvis started
2020-09-30 22:31:16 WARNING OSWindows.py:51 - Could not understand audio, try again
Traceback (most recent call last):
  File "OSWindows.py", line 48, in listen
    cmd = self.listener.recognize_google(audio, language="en-GB")
  File "D:\Program Files\Python364\lib\site-packages\speech_recognition\__init__.py", line 858, in recognize_google
    if not isinstance(actual_result, dict) or len(actual_result.get("alternative", [])) == 0: raise UnknownValueError()
speech_recognition.UnknownValueError
2020-10-03 21:59:13 INFO Core.py:9 - Jarvis started
2020-10-03 21:59:49 WARNING OSWindows.py:56 - Could not understand audio, try again
2020-10-03 21:59:55 WARNING OSWindows.py:56 - Could not understand audio, try again
2020-10-03 22:00:45 INFO Core.py:9 - Jarvis started
2020-10-03 22:00:59 WARNING OSWindows.py:56 - Could not understand audio, try again
2020-10-08 20:07:53 INFO Core.py:9 - Jarvis started
2020-10-08 20:21:11 INFO logger.py:194 - [Logger      ] Record log in C:\Users\james\.kivy\logs\kivy_20-10-08_2.txt
2020-10-08 20:21:11 INFO __init__.py:475 - [Kivy        ] v1.11.1
2020-10-08 20:21:11 INFO __init__.py:478 - [Kivy        ] Installed at "D:\Program Files\Python364\lib\site-packages\kivy\__init__.py"
2020-10-08 20:21:11 INFO __init__.py:479 - [Python      ] v3.6.4 (v3.6.4:d48eceb, Dec 19 2017, 06:54:40) [MSC v.1900 64 bit (AMD64)]
2020-10-08 20:21:11 INFO __init__.py:480 - [Python      ] Interpreter at "D:\Program Files\Python364\python.exe"
2020-10-08 20:21:41 WARNING logger.py:311 - stderr: Traceback (most recent call last):
2020-10-08 20:21:41 WARNING logger.py:311 - stderr:   File "Jarvis.py", line 7, in <module>
2020-10-08 20:21:41 WARNING logger.py:311 - stderr:     main(true_false("Listen? "), true_false("Speak? "))
2020-10-08 20:21:41 WARNING logger.py:311 - stderr:   File "C:\Users\james\Dropbox\Programming\Projects\TTS\Jarvis\src\OSWindows.py", line 178, in main
2020-10-08 20:21:42 WARNING logger.py:311 - stderr:     Core.main(Inputter(to_listen), Outputter(to_speak))
2020-10-08 20:21:42 WARNING logger.py:311 - stderr:   File "C:\Users\james\Dropbox\Programming\Projects\TTS\Jarvis\src\OSWindows.py", line 99, in __init__
2020-10-08 20:21:42 WARNING logger.py:311 - stderr:     self.gTTS = gTTS
2020-10-08 20:21:42 WARNING logger.py:311 - stderr: UnboundLocalError: local variable 'gTTS' referenced before assignment
